Workbook
Name DATA_VAL: Table1[TABLE DETAILS]

Sheet RAW_DATA
A1: Transaction ID | B1: Branch | C1: Product | D1: Quantity | E1: Unit Price | F1: Customer ID | G1: Order Date | H1: Return Qty
A2: T00001 | B2: Lagos | C2: Pasta | D2: N/A | E2: 15000 | F2: C0174 | G2: 46125 | H2: 0
A3: T00002 | B3: Port Harcourt | C3: RICE | D3: 3 | E3: 50000 | F3: C0220 | G3: 46046 | H3: 0
A4: T00003 | B4: Port Harcourt | C4: Rice | D4: 13 | E4: 50000 | F4: C0002 | G4: 46032 | H4: 0
A5: T00004 | B5: Ibadan | C5: Chicken | D5: 18 | E5: 35000 | F5: C0013 | G5: 46091 | H5: 5
A6: T00005 | B6: Abuja | C6: Bread | D6: 11 | E6: 20000 | F6: C0242 | G6: 46048 | H6: 0
A7: T00006 | B7: Lagos | C7: Rice | D7: 1 | E7: 50000 | F7: C0107 | G7: 46089 | H7: 0
A8: T00007 | B8: Lagos | C8: Tomato | D8: 12 | E8: 8000 | F8: C0131 | G8: 46025 | H8: 0
A9: T00008 | B9: Ibadan | C9: Chicken | D9: 4 | E9: 35000 | F9: C0035 | G9: 46180 | H9: 0
A10: T00009 | B10: Abuja | C10: Bread | D10: -1 | E10: 20000 | F10: C0227 | G10: 46079 | H10: 0
A11: T00010 | B11: Ibadan | C11: Eggs | D11: 6 | E11: 12000 | F11: C0282 | G11: 46035 | H11: 5
A12: T00011 | B12: Port Harcourt | C12: Bread | D12: 6 | E12: 20000 | F12: C0225 | G12: 09/01/2026 | H12: 0
A13: T00012 | B13: Abuja | C13: Milk | D13: 3 | E13: 20000 | F13: C0292 | G13: 46177 | H13: 0
A14: T00013 | B14: Lagos | C14: Pasta | D14: 3 | E14: 15000 | F14: C0094 | G14: 46127 | H14: 0
A15: T00014 | B15: Ibadan | C15: Tomato | D15: 7 | E15: 8000 | F15: C0099 | G15: 46043 | H15: 0
A16: T00015 | B16: Port Harcourt | C16: Milk | D16: 21 | E16: 20000 | F16: C0102 | G16: 46101 | H16: 0
A17: T00016 | B17: Abuja | C17: Chicken | D17: 10 | E17: 35000 | F17: C0196 | G17: 46123 | H17: 0
A18: T00017 | B18: Lagos | C18: Eggs | D18: 23 | E18: 12000 | F18: C0283 | G18: 46027 | H18: 0
A19: T00018 | B19: Lagos | C19: Rice | D19: 24 | E19: 50000 | F19: C0278 | G19: 46128 | H19: 3
A20: T00019 | B20: Port Harcourt | C20: Rice | D20: 24 | E20: 50000 | F20: C0033 | G20: 46200 | H20: 0
A21: T00020 | B21: Abuja | C21: Chicken | D21: 25 | E21: 35000 | F21: C0026 | G21: 46120 | H21: 0
A22: T00021 | B22: Ibadan | C22: Chicken | D22: 22 | E22: 35000 | F22: C0278 | G22: 21/06/2026 | H22: 3
A23: T00022 | B23: Lagos | C23: Pasta | D23: 18 | E23: 15000 | F23: C0200 | G23: 46054 | H23: 0
A24: T00023 | B24: Abuja | C24: Cooking Oil | D24: 17 | E24: 28000 | F24: C0103 | G24: 46099 | H24: 0
A25: T00024 | B25: Ibadan | C25: Milk | D25: 8 | E25: 20000 | F25: C0057 | G25: 46169 | H25: 5
A26: T00025 | B26: Ibadan | C26: Chicken | D26: 4 | E26: 70000 | F26: C0052 | G26: 46165 | H26: 0
A27: T00026 | B27: Lagos | C27: Bread | D27: 7 | E27: 20,000 | F27: C0019 | G27: 46081 | H27: 0
A28: T00027 | B28: Lagos | C28: Milk | D28: 1 | E28: 20000 | F28: C0212 | G28: 46148 | H28: 0
A29: T00028 | B29: Abuja | C29: Milk | D29: 11 | E29: 20000 | F29: C0159 | G29: 46067 | H29: 4
A30: T00029 | B30: Ibadan | C30: Tomato | D30: 19 | E30: 8000 | F30: C0295 | G30: 46055 | H30: 0
A31: T00030 | B31: Port Harcourt | C31: Rice | D31: 1 | E31: 50000 | F31: C0206 | G31: 46031 | H31: 0
A32: T00031 | B32: Port Harcourt | C32: Rice | D32: 12 | E32: 50000 | F32: C0151 | G32: 46105 | H32: 0
A33: T00032 | B33: Abuja | C33: Milk | D33: 11 | E33: 20000 | F33: C0261 | G33: 46091 | H33: 0
A34: T00033 | B34: Lagos | C34: Pasta | D34: 24 | E34: 15000 | F34: C0218 | G34: 46043 | H34: 3
A35: T00034 | B35: Lagos | C35: Chicken | D35: 20 | E35: 35000 | F35: C0227 | G35: 46070 | H35: 0
A36: T00035 | B36: Lagos | C36: Tomato | D36: 12 | E36: 8000 | F36: C0236 | G36: 46108 | H36: 0
A37: T00036 | B37: Abuja | C37: Tomato | D37: 4 | E37: 8000 | F37: C0179 | G37: 46159 | H37: 0
A38: T00037 | B38: Ibadan | C38: Tomato | D38: 12 | E38: 8000 | F38: C0238 | G38: 46110 | H38: 0
A39: T00038 | B39: Lagos | C39: Tomato | D39: -6 | E39: 8000 | F39: C0136 | G39: 46139 | H39: 0
... A43: T00042 | B43: Ibadan | C43: Chicken | D43: 6 | E43: 35000 | F43: C0070 | G43: 46119 | H43: 0
...

Sheet CLEANED
A1: Transaction ID | B1: Branch | C1: Product | D1: Quantity | E1: Unit Price | F1: Customer ID | G1: Order Date | H1: Return Qty | I1: are branches correct | J1: valid QTY | K1: is quantity sold > quantity returned? | L1: Unit price is valid | M1: is the date valid | N1: Revenue before return | O1: Amount of order returned | P1: Revenue after return | Q1: Action
A2: T00001 | B2: Lagos | C2: Pasta | D2: N/A | E2: 15000 | F2: C0174 | G2: 46125 | H2: 0 | I2: =IF(OR('CAL-DATA VALIDATION'!$A$2=Table3[[#This Row],[Branch]], 'CAL-DATA VALIDATION'!$A$3=Table3[[#This Row],[Branch]],'CAL-DATA VALIDATION'!$A$4=Table3[[#This Row],[Branch]],'CAL-DATA VALIDATION'!$A$5=Table3[[#This Row],[Branch]]), TRUE, FALSE) -> TRUE | J2: =((ISNUMBER(Table3[[#This Row],[Quantity]]) )* (Table3[[#This Row],[Quantity]]>0))=1 -> FALSE | K2: =((Table3[[#This Row],[Quantity]]>=Table3[[#This Row],[Return Qty]])*(ISNUMBER(Table3[[#This Row],[Quantity]])))=1 -> FALSE | L2: =ISNUMBER(Table3[[#This Row],[Unit Price]]) -> TRUE | M2: =ISNUMBER(Table3[[#This Row],[Order Date]]) -> TRUE | N2: =IFERROR(IF(Table3[[#This Row],[Quantity]]*Table3[[#This Row],[Unit Price]]<0, "N/A", Table3[[#This Row],[Quantity]]*Table3[[#This Row],[Unit Price]]), "N/A") -> N/A | O2: =IFERROR(Table3[[#This Row],[Unit Price]]*Table3[[#This Row],[Return Qty]], "N/A") -> 0 | P2: =IFERROR(IF((Table3[[#This Row],[Revenue before return]]-Table3[[#This Row],[Amount of order returned]])<0, "N/A", Table3[[#This Row],[Revenue before return]]-Table3[[#This Row],[Amount of order returned]]), "N/A") -> N/A | Q2: =IF(AND(Table3[[#This Row],[are branches correct]]=TRUE, Table3[[#This Row],[is quantity sold > quantity returned?]]=TRUE, Table3[[#This Row],[Unit price is valid]]=TRUE,Table3[[#This Row],[is the date valid]]=TRUE,Table3[[#This Row],[valid QTY]]=TRUE), "No action required", "Inspect") -> Inspect
A3: T00002 | B3: Port Harcourt | C3: Rice | D3: 3 | E3: 50000 | F3: C0220 | G3: 46046 | H3: 0 | I3: =IF(OR('CAL-DATA VALIDATION'!$A$2=Table3[[#This Row],[Branch]], 'CAL-DATA VALIDATION'!$A$3=Table3[[#This Row],[Branch]],'CAL-DATA VALIDATION'!$A$4=Table3[[#This Row],[Branch]],'CAL-DATA VALIDATION'!$A$5=Table3[[#This Row],[Branch]]), TRUE, FALSE) -> TRUE | J3: =((ISNUMBER(Table3[[#This Row],[Quantity]]) )* (Table3[[#This Row],[Quantity]]>0))=1 -> TRUE | K3: =((Table3[[#This Row],[Quantity]]>=Table3[[#This Row],[Return Qty]])*(ISNUMBER(Table3[[#This Row],[Quantity]])))=1 -> TRUE | L3: =ISNUMBER(Table3[[#This Row],[Unit Price]]) -> TRUE | M3: =ISNUMBER(Table3[[#This Row],[Order Date]]) -> TRUE | N3: =IFERROR(IF(Table3[[#This Row],[Quantity]]*Table3[[#This Row],[Unit Price]]<0, "N/A", Table3[[#This Row],[Quantity]]*Table3[[#This Row],[Unit Price]]), "N/A") -> 150000 | O3: =IFERROR(Table3[[#This Row],[Unit Price]]*Table3[[#This Row],[Return Qty]], "N/A") -> 0 | P3: =IFERROR(IF((Table3[[#This Row],[Revenue before return]]-Table3[[#This Row],[Amount of order returned]])<0, "N/A", Table3[[#This Row],[Revenue before return]]-Table3[[#This Row],[Amount of order returned]]), "N/A") -> 150000 | Q3: =IF(AND(Table3[[#This Row],[are branches correct]]=TRUE, Table3[[#This Row],[is quantity sold > quantity returned?]]=TRUE, Table3[[#This Row],[Unit price is valid]]=TRUE,Table3[[#This Row],[is the date valid]]=TRUE,Table3[[#This Row],[valid QTY]]=TRUE), "No action required", "Inspect") -> No action required
A4: T00003 | B4: Port Harcourt | C4: Rice | D4: 13 | E4: 50000 | F4: C0002 | G4: 46032 | H4: 0 | I4: =IF(OR('CAL-DATA VALIDATION'!$A$2=Table3[[#This Row],[Branch]], 'CAL-DATA VALIDATION'!$A$3=Table3[[#This Row],[Branch]],'CAL-DATA VALIDATION'!$A$4=Table3[[#This Row],[Branch]],'CAL-DATA VALIDATION'!$A$5=Table3[[#This Row],[Branch]]), TRUE, FALSE) -> TRUE | J4: =((ISNUMBER(Table3[[#This Row],[Quantity]]) )* (Table3[[#This Row],[Quantity]]>0))=1 -> TRUE | K4: =((Table3[[#This Row],[Quantity]]>=Table3[[#This Row],[Return Qty]])*(ISNUMBER(Table3[[#This Row],[Quantity]])))=1 -> TRUE | L4: =ISNUMBER(Table3[[#This Row],[Unit Price]]) -> TRUE | M4: =ISNUMBER(Table3[[#This Row],[Order Date]]) -> TRUE | N4: =IFERROR(IF(Table3[[#This Row],[Quantity]]*Table3[[#This Row],[Unit Price]]<0, "N/A", Table3[[#This Row],[Quantity]]*Table3[[#This Row],[Unit Price]]), "N/A") -> 650000 | O4: =IFERROR(Table3[[#This Row],[Unit Price]]*Table3[[#This Row],[Return Qty]], "N/A") -> 0 | P4: =IFERROR(IF((Table3[[#This Row],[Revenue before return]]-Table3[[#This Row],[Amount of order returned]])<0, "N/A", Table3[[#This Row],[Revenue before return]]-Table3[[#This Row],[Amount of order returned]]), "N/A") -> 650000 | Q4: =IF(AND(Table3[[#This Row],[are branches correct]]=TRUE, Table3[[#This Row],[is quantity sold > quantity returned?]]=TRUE, Table3[[#This Row],[Unit price is valid]]=TRUE,Table3[[#This Row],[is the date valid]]=TRUE,Table3[[#This Row],[valid QTY]]=TRUE), "No action required", "Inspect") -> No action required
A5: T00004 | B5: Ibadan | C5: Chicken | D5: 18 | E5: 35000 | F5: C0013 | G5: 46091 | H5: 5 | I5: =IF(OR('CAL-DATA VALIDATION'!$A$2=Table3[[#This Row],[Branch]], 'CAL-DATA VALIDATION'!$A$3=Table3[[#This Row],[Branch]],'CAL-DATA VALIDATION'!$A$4=Table3[[#This Row],[Branch]],'CAL-DATA VALIDATION'!$A$5=Table3[[#This Row],[Branch]]), TRUE, FALSE) -> TRUE | J5: =((ISNUMBER(Table3[[#This Row],[Quantity]]) )* (Table3[[#This Row],[Quantity]]>0))=1 -> TRUE | K5: =((Table3[[#This Row],[Quantity]]>=Table3[[#This Row],[Return Qty]])*(ISNUMBER(Table3[[#This Row],[Quantity]])))=1 -> TRUE | L5: =ISNUMBER(Table3[[#This Row],[Unit Price]]) -> TRUE | M5: =ISNUMBER(Table3[[#This Row],[Order Date]]) -> TRUE | N5: =IFERROR(IF(Table3[[#This Row],[Quantity]]*Table3[[#This Row],[Unit Price]]<0, "N/A", Table3[[#This Row],[Quantity]]*Table3[[#This Row],[Unit Price]]), "N/A") -> 630000 | O5: =IFERROR(Table3[[#This Row],[Unit Price]]*Table3[[#This Row],[Return Qty]], "N/A") -> 175000 | P5: =IFERROR(IF((Table3[[#This Row],[Revenue before return]]-Table3[[#This Row],[Amount of order returned]])<0, "N/A", Table3[[#This Row],[Revenue before return]]-Table3[[#This Row],[Amount of order returned]]), "N/A") -> 455000 | Q5: =IF(AND(Table3[[#This Row],[are branches correct]]=TRUE, Table3[[#This Row],[is quantity sold > quantity returned?]]=TRUE, Table3[[#This Row],[Unit price is valid]]=TRUE,Table3[[#This Row],[is the date valid]]=TRUE,Table3[[#This Row],[valid QTY]]=TRUE), "No action required", "Inspect") -> No action required
A6: T00005 | B6: Abuja | C6: Bread | D6: 11 | E6: 20000 | F6: C0242 | G6: 46048 | H6: 0 | I6: =IF(OR('CAL-DATA VALIDATION'!$A$2=Table3[[#This Row],[Branch]], 'CAL-DATA VALIDATION'!$A$3=Table3[[#This Row],[Branch]],'CAL-DATA VALIDATION'!$A$4=Table3[[#This Row],[Branch]],'CAL-DATA VALIDATION'!$A$5=Table3[[#This Row],[Branch]]), TRUE, FALSE) -> TRUE | J6: =((ISNUMBER(Table3[[#This Row],[Quantity]]) )* (Table3[[#This Row],[Quantity]]>0))=1 -> TRUE | K6: =((Table3[[#This Row],[Quantity]]>=Table3[[#This Row],[Return Qty]])*(ISNUMBER(Table3[[#This Row],[Quantity]])))=1 -> TRUE | L6: =ISNUMBER(Table3[[#This Row],[Unit Price]]) -> TRUE | M6: =ISNUMBER(Table3[[#This Row],[Order Date]]) -> TRUE | N6: =IFERROR(IF(Table3[[#This Row],[Quantity]]*Table3[[#This Row],[Unit Price]]<0, "N/A", Table3[[#This Row],[Quantity]]*Table3[[#This Row],[Unit Price]]), "N/A") -> 220000 | O6: =IFERROR(Table3[[#This Row],[Unit Price]]*Table3[[#This Row],[Return Qty]], "N/A") -> 0 | P6: =IFERROR(IF((Table3[[#This Row],[Revenue before return]]-Table3[[#This Row],[Amount of order returned]])<0, "N/A", Table3[[#This Row],[Revenue before return]]-Table3[[#This Row],[Amount of order returned]]), "N/A") -> 220000 | Q6: =IF(AND(Table3[[#This Row],[are branches correct]]=TRUE, Table3[[#This Row],[is quantity sold > quantity returned?]]=TRUE, Table3[[#This Row],[Unit price is valid]]=TRUE,Table3[[#This Row],[is the date valid]]=TRUE,Table3[[#This Row],[valid QTY]]=TRUE), "No action required", "Inspect") -> No action required
A7: T00006 | B7: Lagos | C7: Rice | D7: 1 | E7: 50000 | F7: C0107 | G7: 46089 | H7: 0 | I7: =IF(OR('CAL-DATA VALIDATION'!$A$2=Table3[[#This Row],[Branch]], 'CAL-DATA VALIDATION'!$A$3=Table3[[#This Row],[Branch]],'CAL-DATA VALIDATION'!$A$4=Table3[[#This Row],[Branch]],'CAL-DATA VALIDATION'!$A$5=Table3[[#This Row],[Branch]]), TRUE, FALSE) -> TRUE | J7: =((ISNUMBER(Table3[[#This Row],[Quantity]]) )* (Table3[[#This Row],[Quantity]]>0))=1 -> TRUE | K7: =((Table3[[#This Row],[Quantity]]>=Table3[[#This Row],[Return Qty]])*(ISNUMBER(Table3[[#This Row],[Quantity]])))=1 -> TRUE | L7: =ISNUMBER(Table3[[#This Row],[Unit Price]]) -> TRUE | M7: =ISNUMBER(Table3[[#This Row],[Order Date]]) -> TRUE | N7: =IFERROR(IF(Table3[[#This Row],[Quantity]]*Table3[[#This Row],[Unit Price]]<0, "N/A", Table3[[#This Row],[Quantity]]*Table3[[#This Row],[Unit Price]]), "N/A") -> 50000 | O7: =IFERROR(Table3[[#This Row],[Unit Price]]*Table3[[#This Row],[Return Qty]], "N/A") -> 0 | P7: =IFERROR(IF((Table3[[#This Row],[Revenue before return]]-Table3[[#This Row],[Amount of order returned]])<0, "N/A", Table3[[#This Row],[Revenue before return]]-Table3[[#This Row],[Amount of order returned]]), "N/A") -> 50000 | Q7: =IF(AND(Table3[[#This Row],[are branches correct]]=TRUE, Table3[[#This Row],[is quantity sold > quantity returned?]]=TRUE, Table3[[#This Row],[Unit price is valid]]=TRUE,Table3[[#This Row],[is the date valid]]=TRUE,Table3[[#This Row],[valid QTY]]=TRUE), "No action required", "Inspect") -> No action required
A8: T00007 | B8: Lagos | C8: Tomato | D8: 12 | E8: 8000 | F8: C0131 | G8: 46025 | H8: 0 | I8: =IF(OR('CAL-DATA VALIDATION'!$A$2=Table3[[#This Row],[Branch]], 'CAL-DATA VALIDATION'!$A$3=Table3[[#This Row],[Branch]],'CAL-DATA VALIDATION'!$A$4=Table3[[#This Row],[Branch]],'CAL-DATA VALIDATION'!$A$5=Table3[[#This Row],[Branch]]), TRUE, FALSE) -> TRUE | J8: =((ISNUMBER(Table3[[#This Row],[Quantity]]) )* (Table3[[#This Row],[Quantity]]>0))=1 -> TRUE | K8: =((Table3[[#This Row],[Quantity]]>=Table3[[#This Row],[Return Qty]])*(ISNUMBER(Table3[[#This Row],[Quantity]])))=1 -> TRUE | L8: =ISNUMBER(Table3[[#This Row],[Unit Price]]) -> TRUE | M8: =ISNUMBER(Table3[[#This Row],[Order Date]]) -> TRUE | N8: =IFERROR(IF(Table3[[#This Row],[Quantity]]*Table3[[#This Row],[Unit Price]]<0, "N/A", Table3[[#This Row],[Quantity]]*Table3[[#This Row],[Unit Price]]), "N/A") -> 96000 | O8: =IFERROR(Table3[[#This Row],[Unit Price]]*Table3[[#This Row],[Return Qty]], "N/A") -> 0 | P8: =IFERROR(IF((Table3[[#This Row],[Revenue before return]]-Table3[[#This Row],[Amount of order returned]])<0, "N/A", Table3[[#This Row],[Revenue before return]]-Table3[[#This Row],[Amount of order returned]]), "N/A") -> 96000 | Q8: =IF(AND(Table3[[#This Row],[are branches correct]]=TRUE, Table3[[#This Row],[is quantity sold > quantity returned?]]=TRUE, Table3[[#This Row],[Unit price is valid]]=TRUE,Table3[[#This Row],[is the date valid]]=TRUE,Table3[[#This Row],[valid QTY]]=TRUE), "No action required", "Inspect") -> No action required
A9: T00008 | B9: Ibadan | C9: Chicken | D9: 4 | E9: 35000 | F9: C0035 | G9: 46180 | H9: 0 | I9: =IF(OR('CAL-DATA VALIDATION'!$A$2=Table3[[#This Row],[Branch]], 'CAL-DATA VALIDATION'!$A$3=Table3[[#This Row],[Branch]],'CAL-DATA VALIDATION'!$A$4=Table3[[#This Row],[Branch]],'CAL-DATA VALIDATION'!$A$5=Table3[[#This Row],[Branch]]), TRUE, FALSE) -> TRUE | J9: =((ISNUMBER(Table3[[#This Row],[Quantity]]) )* (Table3[[#This Row],[Quantity]]>0))=1 -> TRUE | K9: =((Table3[[#This Row],[Quantity]]>=Table3[[#This Row],[Return Qty]])*(ISNUMBER(Table3[[#This Row],[Quantity]])))=1 -> TRUE | L9: =ISNUMBER(Table3[[#This Row],[Unit Price]]) -> TRUE | M9: =ISNUMBER(Table3[[#This Row],[Order Date]]) -> TRUE | N9: =IFERROR(IF(Table3[[#This Row],[Quantity]]*Table3[[#This Row],[Unit Price]]<0, "N/A", Table3[[#This Row],[Quantity]]*Table3[[#This Row],[Unit Price]]), "N/A") -> 140000 | O9: =IFERROR(Table3[[#This Row],[Unit Price]]*Table3[[#This Row],[Return Qty]], "N/A") -> 0 | P9: =IFERROR(IF((Table3[[#This Row],[Revenue before return]]-Table3[[#This Row],[Amount of order returned]])<0, "N/A", Table3[[#This Row],[Revenue before return]]-Table3[[#This Row],[Amount of order returned]]), "N/A") -> 140000 | Q9: =IF(AND(Table3[[#This Row],[are branches correct]]=TRUE, Table3[[#This Row],[is quantity sold > quantity returned?]]=TRUE, Table3[[#This Row],[Unit price is valid]]=TRUE,Table3[[#This Row],[is the date valid]]=TRUE,Table3[[#This Row],[valid QTY]]=TRUE), "No action required", "Inspect") -> No action required
A10: T00009 | B10: Abuja | C10: Bread | D10: -1 | E10: 20000 | F10: C0227 | G10: 46079 | H10: 0 | I10: =IF(OR('CAL-DATA VALIDATION'!$A$2=Table3[[#This Row],[Branch]], 'CAL-DATA VALIDATION'!$A$3=Table3[[#This Row],[Branch]],'CAL-DATA VALIDATION'!$A$4=Table3[[#This Row],[Branch]],'CAL-DATA VALIDATION'!$A$5=Table3[[#This Row],[Branch]]), TRUE, FALSE) -> TRUE | J10: =((ISNUMBER(Table3[[#This Row],[Quantity]]) )* (Table3[[#This Row],[Quantity]]>0))=1 -> FALSE | K10: =((Table3[[#This Row],[Quantity]]>=Table3[[#This Row],[Return Qty]])*(ISNUMBER(Table3[[#This Row],[Quantity]])))=1 -> FALSE | L10: =ISNUMBER(Table3[[#This Row],[Unit Price]]) -> TRUE | M10: =ISNUMBER(Table3[[#This Row],[Order Date]]) -> TRUE | N10: =IFERROR(IF(Table3[[#This Row],[Quantity]]*Table3[[#This Row],[Unit Price]]<0, "N/A", Table3[[#This Row],[Quantity]]*Table3[[#This Row],[Unit Price]]), "N/A") -> N/A | O10: =IFERROR(Table3[[#This Row],[Unit Price]]*Table3[[#This Row],[Return Qty]], "N/A") -> 0 | P10: =IFERROR(IF((Table3[[#This Row],[Revenue before return]]-Table3[[#This Row],[Amount of order returned]])<0, "N/A", Table3[[#This Row],[Revenue before return]]-Table3[[#This Row],[Amount of order returned]]), "N/A") -> N/A | Q10: =IF(AND(Table3[[#This Row],[are branches correct]]=TRUE, Table3[[#This Row],[is quantity sold > quantity returned?]]=TRUE, Table3[[#This Row],[Unit price is valid]]=TRUE,Table3[[#This Row],[is the date valid]]=TRUE,Table3[[#This Row],[valid QTY]]=TRUE), "No action required", "Inspect") -> Inspect
A11: T00010 | B11: Ibadan | C11: Eggs | D11: 6 | E11: 12000 | F11: C0282 | G11: 46035 | H11: 5 | I11: =IF(OR('CAL-DATA VALIDATION'!$A$2=Table3[[#This Row],[Branch]], 'CAL-DATA VALIDATION'!$A$3=Table3[[#This Row],[Branch]],'CAL-DATA VALIDATION'!$A$4=Table3[[#This Row],[Branch]],'CAL-DATA VALIDATION'!$A$5=Table3[[#This Row],[Branch]]), TRUE, FALSE) -> TRUE | J11: =((ISNUMBER(Table3[[#This Row],[Quantity]]) )* (Table3[[#This Row],[Quantity]]>0))=1 -> TRUE | K11: =((Table3[[#This Row],[Quantity]]>=Table3[[#This Row],[Return Qty]])*(ISNUMBER(Table3[[#This Row],[Quantity]])))=1 -> TRUE | L11: =ISNUMBER(Table3[[#This Row],[Unit Price]]) -> TRUE | M11: =ISNUMBER(Table3[[#This Row],[Order Date]]) -> TRUE | N11: =IFERROR(IF(Table3[[#This Row],[Quantity]]*Table3[[#This Row],[Unit Price]]<0, "N/A", Table3[[#This Row],[Quantity]]*Table3[[#This Row],[Unit Price]]), "N/A") -> 72000 | O11: =IFERROR(Table3[[#This Row],[Unit Price]]*Table3[[#This Row],[Return Qty]], "N/A") -> 60000 | P11: =IFERROR(IF((Table3[[#This Row],[Revenue before return]]-Table3[[#This Row],[Amount of order returned]])<0, "N/A", Table3[[#This Row],[Revenue before return]]-Table3[[#This Row],[Amount of order returned]]), "N/A") -> 12000 | Q11: =IF(AND(Table3[[#This Row],[are branches correct]]=TRUE, Table3[[#This Row],[is quantity sold > quantity returned?]]=TRUE, Table3[[#This Row],[Unit price is valid]]=TRUE,Table3[[#This Row],[is the date valid]]=TRUE,Table3[[#This Row],[valid QTY]]=TRUE), "No action required", "Inspect") -> No action required
A12: T00011 | B12: Port Harcourt | C12: Bread | D12: 6 | E12: 20000 | F12: C0225 | G12: 46031 | H12: 0 | I12: =IF(OR('CAL-DATA VALIDATION'!$A$2=Table3[[#This Row],[Branch]], 'CAL-DATA VALIDATION'!$A$3=Table3[[#This Row],[Branch]],'CAL-DATA VALIDATION'!$A$4=Table3[[#This Row],[Branch]],'CAL-DATA VALIDATION'!$A$5=Table3[[#This Row],[Branch]]), TRUE, FALSE) -> TRUE | J12: =((ISNUMBER(Table3[[#This Row],[Quantity]]) )* (Table3[[#This Row],[Quantity]]>0))=1 -> TRUE | K12: =((Table3[[#This Row],[Quantity]]>=Table3[[#This Row],[Return Qty]])*(ISNUMBER(Table3[[#This Row],[Quantity]])))=1 -> TRUE | L12: =ISNUMBER(Table3[[#This Row],[Unit Price]]) -> TRUE | M12: =ISNUMBER(Table3[[#This Row],[Order Date]]) -> TRUE | N12: =IFERROR(IF(Table3[[#This Row],[Quantity]]*Table3[[#This Row],[Unit Price]]<0, "N/A", Table3[[#This Row],[Quantity]]*Table3[[#This Row],[Unit Price]]), "N/A") -> 120000 | O12: =IFERROR(Table3[[#This Row],[Unit Price]]*Table3[[#This Row],[Return Qty]], "N/A") -> 0 | P12: =IFERROR(IF((Table3[[#This Row],[Revenue before return]]-Table3[[#This Row],[Amount of order returned]])<0, "N/A", Table3[[#This Row],[Revenue before return]]-Table3[[#This Row],[Amount of order returned]]), "N/A") -> 120000 | Q12: =IF(AND(Table3[[#This Row],[are branches correct]]=TRUE, Table3[[#This Row],[is quantity sold > quantity returned?]]=TRUE, Table3[[#This Row],[Unit price is valid]]=TRUE,Table3[[#This Row],[is the date valid]]=TRUE,Table3[[#This Row],[valid QTY]]=TRUE), "No action required", "Inspect") -> No action required
A13: T00012 | B13: Abuja | C13: Milk | D13: 3 | E13: 20000 | F13: C0292 | G13: 46177 | H13: 0 | I13: =IF(OR('CAL-DATA VALIDATION'!$A$2=Table3[[#This Row],[Branch]], 'CAL-DATA VALIDATION'!$A$3=Table3[[#This Row],[Branch]],'CAL-DATA VALIDATION'!$A$4=Table3[[#This Row],[Branch]],'CAL-DATA VALIDATION'!$A$5=Table3[[#This Row],[Branch]]), TRUE, FALSE) -> TRUE | J13: =((ISNUMBER(Table3[[#This Row],[Quantity]]) )* (Table3[[#This Row],[Quantity]]>0))=1 -> TRUE | K13: =((Table3[[#This Row],[Quantity]]>=Table3[[#This Row],[Return Qty]])*(ISNUMBER(Table3[[#This Row],[Quantity]])))=1 -> TRUE | L13: =ISNUMBER(Table3[[#This Row],[Unit Price]]) -> TRUE | M13: =ISNUMBER(Table3[[#This Row],[Order Date]]) -> TRUE | N13: =IFERROR(IF(Table3[[#This Row],[Quantity]]*Table3[[#This Row],[Unit Price]]<0, "N/A", Table3[[#This Row],[Quantity]]*Table3[[#This Row],[Unit Price]]), "N/A") -> 60000 | O13: =IFERROR(Table3[[#This Row],[Unit Price]]*Table3[[#This Row],[Return Qty]], "N/A") -> 0 | P13: =IFERROR(IF((Table3[[#This Row],[Revenue before return]]-Table3[[#This Row],[Amount of order returned]])<0, "N/A", Table3[[#This Row],[Revenue before return]]-Table3[[#This Row],[Amount of order returned]]), "N/A") -> 60000 | Q13: =IF(AND(Table3[[#This Row],[are branches correct]]=TRUE, Table3[[#This Row],[is quantity sold > quantity returned?]]=TRUE, Table3[[#This Row],[Unit price is valid]]=TRUE,Table3[[#This Row],[is the date valid]]=TRUE,Table3[[#This Row],[valid QTY]]=TRUE), "No action required", "Inspect") -> No action required
A14: T00013 | B14: Lagos | C14: Pasta | D14: 3 | E14: 15000 | F14: C0094 | G14: 46127 | H14: 0 | I14: =IF(OR('CAL-DATA VALIDATION'!$A$2=Table3[[#This Row],[Branch]], 'CAL-DATA VALIDATION'!$A$3=Table3[[#This Row],[Branch]],'CAL-DATA VALIDATION'!$A$4=Table3[[#This Row],[Branch]],'CAL-DATA VALIDATION'!$A$5=Table3[[#This Row],[Branch]]), TRUE, FALSE) -> TRUE | J14: =((ISNUMBER(Table3[[#This Row],[Quantity]]) )* (Table3[[#This Row],[Quantity]]>0))=1 -> TRUE | K14: =((Table3[[#This Row],[Quantity]]>=Table3[[#This Row],[Return Qty]])*(ISNUMBER(Table3[[#This Row],[Quantity]])))=1 -> TRUE | L14: =ISNUMBER(Table3[[#This Row],[Unit Price]]) -> TRUE | M14: =ISNUMBER(Table3[[#This Row],[Order Date]]) -> TRUE | N14: =IFERROR(IF(Table3[[#This Row],[Quantity]]*Table3[[#This Row],[Unit Price]]<0, "N/A", Table3[[#This Row],[Quantity]]*Table3[[#This Row],[Unit Price]]), "N/A") -> 45000 | O14: =IFERROR(Table3[[#This Row],[Unit Price]]*Table3[[#This Row],[Return Qty]], "N/A") -> 0 | P14: =IFERROR(IF((Table3[[#This Row],[Revenue before return]]-Table3[[#This Row],[Amount of order returned]])<0, "N/A", Table3[[#This Row],[Revenue before return]]-Table3[[#This Row],[Amount of order returned]]), "N/A") -> 45000 | Q14: =IF(AND(Table3[[#This Row],[are branches correct]]=TRUE, Table3[[#This Row],[is quantity sold > quantity returned?]]=TRUE, Table3[[#This Row],[Unit price is valid]]=TRUE,Table3[[#This Row],[is the date valid]]=TRUE,Table3[[#This Row],[valid QTY]]=TRUE), "No action required", "Inspect") -> No action required
... A43: T00042 | B43: Ibadan | C43: Chicken | D43: 6 | E43: 35000 | F43: C0070 | G43: 46119 | H43: 0 | I43: =IF(OR('CAL-DATA VALIDATION'!$A$2=Table3[[#This Row],[Branch]], 'CAL-DATA VALIDATION'!$A$3=Table3[[#This Row],[Branch]],'CAL-DATA VALIDATION'!$A$4=Table3[[#This Row],[Branch]],'CAL-DATA VALIDATION'!$A$5=Table3[[#This Row],[Branch]]), TRUE, FALSE) -> TRUE | J43: =((ISNUMBER(Table3[[#This Row],[Quantity]]) )* (Table3[[#This Row],[Quantity]]>0))=1 -> TRUE | K43: =((Table3[[#This Row],[Quantity]]>=Table3[[#This Row],[Return Qty]])*(ISNUMBER(Table3[[#This Row],[Quantity]])))=1 -> TRUE | L43: =ISNUMBER(Table3[[#This Row],[Unit Price]]) -> TRUE | M43: =ISNUMBER(Table3[[#This Row],[Order Date]]) -> TRUE | N43: =IFERROR(IF(Table3[[#This Row],[Quantity]]*Table3[[#This Row],[Unit Price]]<0, "N/A", Table3[[#This Row],[Quantity]]*Table3[[#This Row],[Unit Price]]), "N/A") -> 210000 | O43: =IFERROR(Table3[[#This Row],[Unit Price]]*Table3[[#This Row],[Return Qty]], "N/A") -> 0 | P43: =IFERROR(IF((Table3[[#This Row],[Revenue before return]]-Table3[[#This Row],[Amount of order returned]])<0, "N/A", Table3[[#This Row],[Revenue before return]]-Table3[[#This Row],[Amount of order returned]]), "N/A") -> 210000 | Q43: =IF(AND(Table3[[#This Row],[are branches correct]]=TRUE, Table3[[#This Row],[is quantity sold > quantity returned?]]=TRUE, Table3[[#This Row],[Unit price is valid]]=TRUE,Table3[[#This Row],[is the date valid]]=TRUE,Table3[[#This Row],[valid QTY]]=TRUE), "No action required", "Inspect") -> No action required
A44: T00043 | B44: Ibadan | C44: Bread | D44: 5 | E44: 20000 | F44: C0039 | G44: N/A | H44: 1 | I44: =IF(OR('CAL-DATA VALIDATION'!$A$2=Table3[[#This Row],[Branch]], 'CAL-DATA VALIDATION'!$A$3=Table3[[#This Row],[Branch]],'CAL-DATA VALIDATION'!$A$4=Table3[[#This Row],[Branch]],'CAL-DATA VALIDATION'!$A$5=Table3[[#This Row],[Branch]]), TRUE, FALSE) -> TRUE | J44: =((ISNUMBER(Table3[[#This Row],[Quantity]]) )* (Table3[[#This Row],[Quantity]]>0))=1 -> TRUE | K44: =((Table3[[#This Row],[Quantity]]>=Table3[[#This Row],[Return Qty]])*(ISNUMBER(Table3[[#This Row],[Quantity]])))=1 -> TRUE | L44: =ISNUMBER(Table3[[#This Row],[Unit Price]]) -> TRUE | M44: =ISNUMBER(Table3[[#This Row],[Order Date]]) -> FALSE | N44: =IFERROR(IF(Table3[[#This Row],[Quantity]]*Table3[[#This Row],[Unit Price]]<0, "N/A", Table3[[#This Row],[Quantity]]*Table3[[#This Row],[Unit Price]]), "N/A") -> 100000 | O44: =IFERROR(Table3[[#This Row],[Unit Price]]*Table3[[#This Row],[Return Qty]], "N/A") -> 20000 | P44: =IFERROR(IF((Table3[[#This Row],[Revenue before return]]-Table3[[#This Row],[Amount of order returned]])<0, "N/A", Table3[[#This Row],[Revenue before return]]-Table3[[#This Row],[Amount of order returned]]), "N/A") -> 80000 | Q44: =IF(AND(Table3[[#This Row],[are branches correct]]=TRUE, Table3[[#This Row],[is quantity sold > quantity returned?]]=TRUE, Table3[[#This Row],[Unit price is valid]]=TRUE,Table3[[#This Row],[is the date valid]]=TRUE,Table3[[#This Row],[valid QTY]]=TRUE), "No action required", "Inspect") -> Inspect
A45: T00044 | B45: Abuja | C45: Eggs | D45: 8 | E45: 12000 | F45: C0184 | G45: 46177 | H45: 0 | I45: =IF(OR('CAL-DATA VALIDATION'!$A$2=Table3[[#This Row],[Branch]], 'CAL-DATA VALIDATION'!$A$3=Table3[[#This Row],[Branch]],'CAL-DATA VALIDATION'!$A$4=Table3[[#This Row],[Branch]],'CAL-DATA VALIDATION'!$A$5=Table3[[#This Row],[Branch]]), TRUE, FALSE) -> TRUE | J45: =((ISNUMBER(Table3[[#This Row],[Quantity]]) )* (Table3[[#This Row],[Quantity]]>0))=1 -> TRUE | K45: =((Table3[[#This Row],[Quantity]]>=Table3[[#This Row],[Return Qty]])*(ISNUMBER(Table3[[#This Row],[Quantity]])))=1 -> TRUE | L45: =ISNUMBER(Table3[[#This Row],[Unit Price]]) -> TRUE | M45: =ISNUMBER(Table3[[#This Row],[Order Date]]) -> TRUE | N45: =IFERROR(IF(Table3[[#This Row],[Quantity]]*Table3[[#This Row],[Unit Price]]<0, "N/A", Table3[[#This Row],[Quantity]]*Table3[[#This Row],[Unit Price]]), "N/A") -> 96000 | O45: =IFERROR(Table3[[#This Row],[Unit Price]]*Table3[[#This Row],[Return Qty]], "N/A") -> 0 | P45: =IFERROR(IF((Table3[[#This Row],[Revenue before return]]-Table3[[#This Row],[Amount of order returned]])<0, "N/A", Table3[[#This Row],[Revenue before return]]-Table3[[#This Row],[Amount of order returned]]), "N/A") -> 96000 | Q45: =IF(AND(Table3[[#This Row],[are branches correct]]=TRUE, Table3[[#This Row],[is quantity sold > quantity returned?]]=TRUE, Table3[[#This Row],[Unit price is valid]]=TRUE,Table3[[#This Row],[is the date valid]]=TRUE,Table3[[#This Row],[valid QTY]]=TRUE), "No action required", "Inspect") -> No action required
A46: T00045 | B46: Ibadan | C46: Bread | D46: 6 | E46: 20000 | F46: C0119 | G46: 46039 | H46: 0 | I46: =IF(OR('CAL-DATA VALIDATION'!$A$2=Table3[[#This Row],[Branch]], 'CAL-DATA VALIDATION'!$A$3=Table3[[#This Row],[Branch]],'CAL-DATA VALIDATION'!$A$4=Table3[[#This Row],[Branch]],'CAL-DATA VALIDATION'!$A$5=Table3[[#This Row],[Branch]]), TRUE, FALSE) -> TRUE | J46: =((ISNUMBER(Table3[[#This Row],[Quantity]]) )* (Table3[[#This Row],[Quantity]]>0))=1 -> TRUE | K46: =((Table3[[#This Row],[Quantity]]>=Table3[[#This Row],[Return Qty]])*(ISNUMBER(Table3[[#This Row],[Quantity]])))=1 -> TRUE | L46: =ISNUMBER(Table3[[#This Row],[Unit Price]]) -> TRUE | M46: =ISNUMBER(Table3[[#This Row],[Order Date]]) -> TRUE | N46: =IFERROR(IF(Table3[[#This Row],[Quantity]]*Table3[[#This Row],[Unit Price]]<0, "N/A", Table3[[#This Row],[Quantity]]*Table3[[#This Row],[Unit Price]]), "N/A") -> 120000 | O46: =IFERROR(Table3[[#This Row],[Unit Price]]*Table3[[#This Row],[Return Qty]], "N/A") -> 0 | P46: =IFERROR(IF((Table3[[#This Row],[Revenue before return]]-Table3[[#This Row],[Amount of order returned]])<0, "N/A", Table3[[#This Row],[Revenue before return]]-Table3[[#This Row],[Amount of order returned]]), "N/A") -> 120000 | Q46: =IF(AND(Table3[[#This Row],[are branches correct]]=TRUE, Table3[[#This Row],[is quantity sold > quantity returned?]]=TRUE, Table3[[#This Row],[Unit price is valid]]=TRUE,Table3[[#This Row],[is the date valid]]=TRUE,Table3[[#This Row],[valid QTY]]=TRUE), "No action required", "Inspect") -> No action required
A47: T00046 | B47: Ibadan | C47: Pasta | D47: 23 | E47: 15000 | F47: C0257 | G47: 46182 | H47: 2 | I47: =IF(OR('CAL-DATA VALIDATION'!$A$2=Table3[[#This Row],[Branch]], 'CAL-DATA VALIDATION'!$A$3=Table3[[#This Row],[Branch]],'CAL-DATA VALIDATION'!$A$4=Table3[[#This Row],[Branch]],'CAL-DATA VALIDATION'!$A$5=Table3[[#This Row],[Branch]]), TRUE, FALSE) -> TRUE | J47: =((ISNUMBER(Table3[[#This Row],[Quantity]]) )* (Table3[[#This Row],[Quantity]]>0))=1 -> TRUE | K47: =((Table3[[#This Row],[Quantity]]>=Table3[[#This Row],[Return Qty]])*(ISNUMBER(Table3[[#This Row],[Quantity]])))=1 -> TRUE | L47: =ISNUMBER(Table3[[#This Row],[Unit Price]]) -> TRUE | M47: =ISNUMBER(Table3[[#This Row],[Order Date]]) -> TRUE | N47: =IFERROR(IF(Table3[[#This Row],[Quantity]]*Table3[[#This Row],[Unit Price]]<0, "N/A", Table3[[#This Row],[Quantity]]*Table3[[#This Row],[Unit Price]]), "N/A") -> 345000 | O47: =IFERROR(Table3[[#This Row],[Unit Price]]*Table3[[#This Row],[Return Qty]], "N/A") -> 30000 | P47: =IFERROR(IF((Table3[[#This Row],[Revenue before return]]-Table3[[#This Row],[Amount of order returned]])<0, "N/A", Table3[[#This Row],[Revenue before return]]-Table3[[#This Row],[Amount of order returned]]), "N/A") -> 315000 | Q47: =IF(AND(Table3[[#This Row],[are branches correct]]=TRUE, Table3[[#This Row],[is quantity sold > quantity returned?]]=TRUE, Table3[[#This Row],[Unit price is valid]]=TRUE,Table3[[#This Row],[is the date valid]]=TRUE,Table3[[#This Row],[valid QTY]]=TRUE), "No action required", "Inspect") -> No action required
A48: T00047 | B48: Ibadan | C48: Bread | D48: N/A | E48: 20000 | F48: C0228 | G48: 46189 | H48: 0 | I48: =IF(OR('CAL-DATA VALIDATION'!$A$2=Table3[[#This Row],[Branch]], 'CAL-DATA VALIDATION'!$A$3=Table3[[#This Row],[Branch]],'CAL-DATA VALIDATION'!$A$4=Table3[[#This Row],[Branch]],'CAL-DATA VALIDATION'!$A$5=Table3[[#This Row],[Branch]]), TRUE, FALSE) -> TRUE | J48: =((ISNUMBER(Table3[[#This Row],[Quantity]]) )* (Table3[[#This Row],[Quantity]]>0))=1 -> FALSE | K48: =((Table3[[#This Row],[Quantity]]>=Table3[[#This Row],[Return Qty]])*(ISNUMBER(Table3[[#This Row],[Quantity]])))=1 -> FALSE | L48: =ISNUMBER(Table3[[#This Row],[Unit Price]]) -> TRUE | M48: =ISNUMBER(Table3[[#This Row],[Order Date]]) -> TRUE | N48: =IFERROR(IF(Table3[[#This Row],[Quantity]]*Table3[[#This Row],[Unit Price]]<0, "N/A", Table3[[#This Row],[Quantity]]*Table3[[#This Row],[Unit Price]]), "N/A") -> N/A | O48: =IFERROR(Table3[[#This Row],[Unit Price]]*Table3[[#This Row],[Return Qty]], "N/A") -> 0 | P48: =IFERROR(IF((Table3[[#This Row],[Revenue before return]]-Table3[[#This Row],[Amount of order returned]])<0, "N/A", Table3[[#This Row],[Revenue before return]]-Table3[[#This Row],[Amount of order returned]]), "N/A") -> N/A | Q48: =IF(AND(Table3[[#This Row],[are branches correct]]=TRUE, Table3[[#This Row],[is quantity sold > quantity returned?]]=TRUE, Table3[[#This Row],[Unit price is valid]]=TRUE,Table3[[#This Row],[is the date valid]]=TRUE,Table3[[#This Row],[valid QTY]]=TRUE), "No action required", "Inspect") -> Inspect
A49: T00048 | B49: Abuja | C49: Eggs | D49: 5 | E49: 12000 | F49: C0264 | G49: 46172 | H49: 0 | I49: =IF(OR('CAL-DATA VALIDATION'!$A$2=Table3[[#This Row],[Branch]], 'CAL-DATA VALIDATION'!$A$3=Table3[[#This Row],[Branch]],'CAL-DATA VALIDATION'!$A$4=Table3[[#This Row],[Branch]],'CAL-DATA VALIDATION'!$A$5=Table3[[#This Row],[Branch]]), TRUE, FALSE) -> TRUE | J49: =((ISNUMBER(Table3[[#This Row],[Quantity]]) )* (Table3[[#This Row],[Quantity]]>0))=1 -> TRUE | K49: =((Table3[[#This Row],[Quantity]]>=Table3[[#This Row],[Return Qty]])*(ISNUMBER(Table3[[#This Row],[Quantity]])))=1 -> TRUE | L49: =ISNUMBER(Table3[[#This Row],[Unit Price]]) -> TRUE | M49: =ISNUMBER(Table3[[#This Row],[Order Date]]) -> TRUE | N49: =IFERROR(IF(Table3[[#This Row],[Quantity]]*Table3[[#This Row],[Unit Price]]<0, "N/A", Table3[[#This Row],[Quantity]]*Table3[[#This Row],[Unit Price]]), "N/A") -> 60000 | O49: =IFERROR(Table3[[#This Row],[Unit Price]]*Table3[[#This Row],[Return Qty]], "N/A") -> 0 | P49: =IFERROR(IF((Table3[[#This Row],[Revenue before return]]-Table3[[#This Row],[Amount of order returned]])<0, "N/A", Table3[[#This Row],[Revenue before return]]-Table3[[#This Row],[Amount of order returned]]), "N/A") -> 60000 | Q49: =IF(AND(Table3[[#This Row],[are branches correct]]=TRUE, Table3[[#This Row],[is quantity sold > quantity returned?]]=TRUE, Table3[[#This Row],[Unit price is valid]]=TRUE,Table3[[#This Row],[is the date valid]]=TRUE,Table3[[#This Row],[valid QTY]]=TRUE), "No action required", "Inspect") -> No action required
A50: T00049 | B50: Ibadan | C50: Rice | D50: 5 | E50: 50000 | F50: C0067 | G50: 46193 | H50: 0 | I50: =IF(OR('CAL-DATA VALIDATION'!$A$2=Table3[[#This Row],[Branch]], 'CAL-DATA VALIDATION'!$A$3=Table3[[#This Row],[Branch]],'CAL-DATA VALIDATION'!$A$4=Table3[[#This Row],[Branch]],'CAL-DATA VALIDATION'!$A$5=Table3[[#This Row],[Branch]]), TRUE, FALSE) -> TRUE | J50: =((ISNUMBER(Table3[[#This Row],[Quantity]]) )* (Table3[[#This Row],[Quantity]]>0))=1 -> TRUE | K50: =((Table3[[#This Row],[Quantity]]>=Table3[[#This Row],[Return Qty]])*(ISNUMBER(Table3[[#This Row],[Quantity]])))=1 -> TRUE | L50: =ISNUMBER(Table3[[#This Row],[Unit Price]]) -> TRUE | M50: =ISNUMBER(Table3[[#This Row],[Order Date]]) -> TRUE | N50: =IFERROR(IF(Table3[[#This Row],[Quantity]]*Table3[[#This Row],[Unit Price]]<0, "N/A", Table3[[#This Row],[Quantity]]*Table3[[#This Row],[Unit Price]]), "N/A") -> 250000 | O50: =IFERROR(Table3[[#This Row],[Unit Price]]*Table3[[#This Row],[Return Qty]], "N/A") -> 0 | P50: =IFERROR(IF((Table3[[#This Row],[Revenue before return]]-Table3[[#This Row],[Amount of order returned]])<0, "N/A", Table3[[#This Row],[Revenue before return]]-Table3[[#This Row],[Amount of order returned]]), "N/A") -> 250000 | Q50: =IF(AND(Table3[[#This Row],[are branches correct]]=TRUE, Table3[[#This Row],[is quantity sold > quantity returned?]]=TRUE, Table3[[#This Row],[Unit price is valid]]=TRUE,Table3[[#This Row],[is the date valid]]=TRUE,Table3[[#This Row],[valid QTY]]=TRUE), "No action required", "Inspect") -> No action required
A51: T00050 | B51: Lagos | C51: Tomato | D51: 17 | E51: 8000 | F51: C0035 | G51: 46079 | H51: 3 | I51: =IF(OR('CAL-DATA VALIDATION'!$A$2=Table3[[#This Row],[Branch]], 'CAL-DATA VALIDATION'!$A$3=Table3[[#This Row],[Branch]],'CAL-DATA VALIDATION'!$A$4=Table3[[#This Row],[Branch]],'CAL-DATA VALIDATION'!$A$5=Table3[[#This Row],[Branch]]), TRUE, FALSE) -> TRUE | J51: =((ISNUMBER(Table3[[#This Row],[Quantity]]) )* (Table3[[#This Row],[Quantity]]>0))=1 -> TRUE | K51: =((Table3[[#This Row],[Quantity]]>=Table3[[#This Row],[Return Qty]])*(ISNUMBER(Table3[[#This Row],[Quantity]])))=1 -> TRUE | L51: =ISNUMBER(Table3[[#This Row],[Unit Price]]) -> TRUE | M51: =ISNUMBER(Table3[[#This Row],[Order Date]]) -> TRUE | N51: =IFERROR(IF(Table3[[#This Row],[Quantity]]*Table3[[#This Row],[Unit Price]]<0, "N/A", Table3[[#This Row],[Quantity]]*Table3[[#This Row],[Unit Price]]), "N/A") -> 136000 | O51: =IFERROR(Table3[[#This Row],[Unit Price]]*Table3[[#This Row],[Return Qty]], "N/A") -> 24000 | P51: =IFERROR(IF((Table3[[#This Row],[Revenue before return]]-Table3[[#This Row],[Amount of order returned]])<0, "N/A", Table3[[#This Row],[Revenue before return]]-Table3[[#This Row],[Amount of order returned]]), "N/A") -> 112000 | Q51: =IF(AND(Table3[[#This Row],[are branches correct]]=TRUE, Table3[[#This Row],[is quantity sold > quantity returned?]]=TRUE, Table3[[#This Row],[Unit price is valid]]=TRUE,Table3[[#This Row],[is the date valid]]=TRUE,Table3[[#This Row],[valid QTY]]=TRUE), "No action required", "Inspect") -> No action required
A52: T00051 | B52: Abuja | C52: Cooking Oil | D52: 16 | E52: 28000 | F52: C0178 | G52: 46134 | H52: 0 | I52: =IF(OR('CAL-DATA VALIDATION'!$A$2=Table3[[#This Row],[Branch]], 'CAL-DATA VALIDATION'!$A$3=Table3[[#This Row],[Branch]],'CAL-DATA VALIDATION'!$A$4=Table3[[#This Row],[Branch]],'CAL-DATA VALIDATION'!$A$5=Table3[[#This Row],[Branch]]), TRUE, FALSE) -> TRUE | J52: =((ISNUMBER(Table3[[#This Row],[Quantity]]) )* (Table3[[#This Row],[Quantity]]>0))=1 -> TRUE | K52: =((Table3[[#This Row],[Quantity]]>=Table3[[#This Row],[Return Qty]])*(ISNUMBER(Table3[[#This Row],[Quantity]])))=1 -> TRUE | L52: =ISNUMBER(Table3[[#This Row],[Unit Price]]) -> TRUE | M52: =ISNUMBER(Table3[[#This Row],[Order Date]]) -> TRUE | N52: =IFERROR(IF(Table3[[#This Row],[Quantity]]*Table3[[#This Row],[Unit Price]]<0, "N/A", Table3[[#This Row],[Quantity]]*Table3[[#This Row],[Unit Price]]), "N/A") -> 448000 | O52: =IFERROR(Table3[[#This Row],[Unit Price]]*Table3[[#This Row],[Return Qty]], "N/A") -> 0 | P52: =IFERROR(IF((Table3[[#This Row],[Revenue before return]]-Table3[[#This Row],[Amount of order returned]])<0, "N/A", Table3[[#This Row],[Revenue before return]]-Table3[[#This Row],[Amount of order returned]]), "N/A") -> 448000 | Q52: =IF(AND(Table3[[#This Row],[are branches correct]]=TRUE, Table3[[#This Row],[is quantity sold > quantity returned?]]=TRUE, Table3[[#This Row],[Unit price is valid]]=TRUE,Table3[[#This Row],[is the date valid]]=TRUE,Table3[[#This Row],[valid QTY]]=TRUE), "No action required", "Inspect") -> No action required
A53: T00052 | B53: Port Harcourt | C53: Milk | D53: 11 | E53: 20000 | F53: C0099 | G53: 46048 | H53: 0 | I53: =IF(OR('CAL-DATA VALIDATION'!$A$2=Table3[[#This Row],[Branch]], 'CAL-DATA VALIDATION'!$A$3=Table3[[#This Row],[Branch]],'CAL-DATA VALIDATION'!$A$4=Table3[[#This Row],[Branch]],'CAL-DATA VALIDATION'!$A$5=Table3[[#This Row],[Branch]]), TRUE, FALSE) -> TRUE | J53: =((ISNUMBER(Table3[[#This Row],[Quantity]]) )* (Table3[[#This Row],[Quantity]]>0))=1 -> TRUE | K53: =((Table3[[#This Row],[Quantity]]>=Table3[[#This Row],[Return Qty]])*(ISNUMBER(Table3[[#This Row],[Quantity]])))=1 -> TRUE | L53: =ISNUMBER(Table3[[#This Row],[Unit Price]]) -> TRUE | M53: =ISNUMBER(Table3[[#This Row],[Order Date]]) -> TRUE | N53: =IFERROR(IF(Table3[[#This Row],[Quantity]]*Table3[[#This Row],[Unit Price]]<0, "N/A", Table3[[#This Row],[Quantity]]*Table3[[#This Row],[Unit Price]]), "N/A") -> 220000 | O53: =IFERROR(Table3[[#This Row],[Unit Price]]*Table3[[#This Row],[Return Qty]], "N/A") -> 0 | P53: =IFERROR(IF((Table3[[#This Row],[Revenue before return]]-Table3[[#This Row],[Amount of order returned]])<0, "N/A", Table3[[#This Row],[Revenue before return]]-Table3[[#This Row],[Amount of order returned]]), "N/A") -> 220000 | Q53: =IF(AND(Table3[[#This Row],[are branches correct]]=TRUE, Table3[[#This Row],[is quantity sold > quantity returned?]]=TRUE, Table3[[#This Row],[Unit price is valid]]=TRUE,Table3[[#This Row],[is the date valid]]=TRUE,Table3[[#This Row],[valid QTY]]=TRUE), "No action required", "Inspect") -> No action required
A54: T00053 | B54: Lagos | C54: Cooking Oil | D54: 9 | E54: 28000 | F54: C0208 | G54: 46072 | H54: 0 | I54: =IF(OR('CAL-DATA VALIDATION'!$A$2=Table3[[#This Row],[Branch]], 'CAL-DATA VALIDATION'!$A$3=Table3[[#This Row],[Branch]],'CAL-DATA VALIDATION'!$A$4=Table3[[#This Row],[Branch]],'CAL-DATA VALIDATION'!$A$5=Table3[[#This Row],[Branch]]), TRUE, FALSE) -> TRUE | J54: =((ISNUMBER(Table3[[#This Row],[Quantity]]) )* (Table3[[#This Row],[Quantity]]>0))=1 -> TRUE | K54: =((Table3[[#This Row],[Quantity]]>=Table3[[#This Row],[Return Qty]])*(ISNUMBER(Table3[[#This Row],[Quantity]])))=1 -> TRUE | L54: =ISNUMBER(Table3[[#This Row],[Unit Price]]) -> TRUE | M54: =ISNUMBER(Table3[[#This Row],[Order Date]]) -> TRUE | N54: =IFERROR(IF(Table3[[#This Row],[Quantity]]*Table3[[#This Row],[Unit Price]]<0, "N/A", Table3[[#This Row],[Quantity]]*Table3[[#This Row],[Unit Price]]), "N/A") -> 252000 | O54: =IFERROR(Table3[[#This Row],[Unit Price]]*Table3[[#This Row],[Return Qty]], "N/A") -> 0 | P54: =IFERROR(IF((Table3[[#This Row],[Revenue before return]]-Table3[[#This Row],[Amount of order returned]])<0, "N/A", Table3[[#This Row],[Revenue before return]]-Table3[[#This Row],[Amount of order returned]]), "N/A") -> 252000 | Q54: =IF(AND(Table3[[#This Row],[are branches correct]]=TRUE, Table3[[#This Row],[is quantity sold > quantity returned?]]=TRUE, Table3[[#This Row],[Unit price is valid]]=TRUE,Table3[[#This Row],[is the date valid]]=TRUE,Table3[[#This Row],[valid QTY]]=TRUE), "No action required", "Inspect") -> No action required
A55: T00054 | B55: Ibadan | C55: Milk | D55: 24 | E55: 20000 | F55: C0146 | G55: 46182 | H55: 0 | I55: =IF(OR('CAL-DATA VALIDATION'!$A$2=Table3[[#This Row],[Branch]], 'CAL-DATA VALIDATION'!$A$3=Table3[[#This Row],[Branch]],'CAL-DATA VALIDATION'!$A$4=Table3[[#This Row],[Branch]],'CAL-DATA VALIDATION'!$A$5=Table3[[#This Row],[Branch]]), TRUE, FALSE) -> TRUE | J55: =((ISNUMBER(Table3[[#This Row],[Quantity]]) )* (Table3[[#This Row],[Quantity]]>0))=1 -> TRUE | K55: =((Table3[[#This Row],[Quantity]]>=Table3[[#This Row],[Return Qty]])*(ISNUMBER(Table3[[#This Row],[Quantity]])))=1 -> TRUE | L55: =ISNUMBER(Table3[[#This Row],[Unit Price]]) -> TRUE | M55: =ISNUMBER(Table3[[#This Row],[Order Date]]) -> TRUE | N55: =IFERROR(IF(Table3[[#This Row],[Quantity]]*Table3[[#This Row],[Unit Price]]<0, "N/A", Table3[[#This Row],[Quantity]]*Table3[[#This Row],[Unit Price]]), "N/A") -> 480000 | O55: =IFERROR(Table3[[#This Row],[Unit Price]]*Table3[[#This Row],[Return Qty]], "N/A") -> 0 | P55: =IFERROR(IF((Table3[[#This Row],[Revenue before return]]-Table3[[#This Row],[Amount of order returned]])<0, "N/A", Table3[[#This Row],[Revenue before return]]-Table3[[#This Row],[Amount of order returned]]), "N/A") -> 480000 | Q55: =IF(AND(Table3[[#This Row],[are branches correct]]=TRUE, Table3[[#This Row],[is quantity sold > quantity returned?]]=TRUE, Table3[[#This Row],[Unit price is valid]]=TRUE,Table3[[#This Row],[is the date valid]]=TRUE,Table3[[#This Row],[valid QTY]]=TRUE), "No action required", "Inspect") -> No action required
A56: T00055 | B56: ABUJA | C56: Rice | D56: 15 | E56: 50000 | F56: C0083 | G56: 46075 | H56: 0 | I56: =IF(OR('CAL-DATA VALIDATION'!$A$2=Table3[[#This Row],[Branch]], 'CAL-DATA VALIDATION'!$A$3=Table3[[#This Row],[Branch]],'CAL-DATA VALIDATION'!$A$4=Table3[[#This Row],[Branch]],'CAL-DATA VALIDATION'!$A$5=Table3[[#This Row],[Branch]]), TRUE, FALSE) -> TRUE | J56: =((ISNUMBER(Table3[[#This Row],[Quantity]]) )* (Table3[[#This Row],[Quantity]]>0))=1 -> TRUE | K56: =((Table3[[#This Row],[Quantity]]>=Table3[[#This Row],[Return Qty]])*(ISNUMBER(Table3[[#This Row],[Quantity]])))=1 -> TRUE | L56: =ISNUMBER(Table3[[#This Row],[Unit Price]]) -> TRUE | M56: =ISNUMBER(Table3[[#This Row],[Order Date]]) -> TRUE | N56: =IFERROR(IF(Table3[[#This Row],[Quantity]]*Table3[[#This Row],[Unit Price]]<0, "N/A", Table3[[#This Row],[Quantity]]*Table3[[#This Row],[Unit Price]]), "N/A") -> 750000 | O56: =IFERROR(Table3[[#This Row],[Unit Price]]*Table3[[#This Row],[Return Qty]], "N/A") -> 0 | P56: =IFERROR(IF((Table3[[#This Row],[Revenue before return]]-Table3[[#This Row],[Amount of order returned]])<0, "N/A", Table3[[#This Row],[Revenue before return]]-Table3[[#This Row],[Amount of order returned]]), "N/A") -> 750000 | Q56: =IF(AND(Table3[[#This Row],[are branches correct]]=TRUE, Table3[[#This Row],[is quantity sold > quantity returned?]]=TRUE, Table3[[#This Row],[Unit price is valid]]=TRUE,Table3[[#This Row],[is the date valid]]=TRUE,Table3[[#This Row],[valid QTY]]=TRUE), "No action required", "Inspect") -> No action required
A57: T00056 | B57: Ibadan | C57: Rice | D57: 14 | E57: 50000 | F57: C0052 | G57: 46079 | H57: 0 | I57: =IF(OR('CAL-DATA VALIDATION'!$A$2=Table3[[#This Row],[Branch]], 'CAL-DATA VALIDATION'!$A$3=Table3[[#This Row],[Branch]],'CAL-DATA VALIDATION'!$A$4=Table3[[#This Row],[Branch]],'CAL-DATA VALIDATION'!$A$5=Table3[[#This Row],[Branch]]), TRUE, FALSE) -> TRUE | J57: =((ISNUMBER(Table3[[#This Row],[Quantity]]) )* (Table3[[#This Row],[Quantity]]>0))=1 -> TRUE | K57: =((Table3[[#This Row],[Quantity]]>=Table3[[#This Row],[Return Qty]])*(ISNUMBER(Table3[[#This Row],[Quantity]])))=1 -> TRUE | L57: =ISNUMBER(Table3[[#This Row],[Unit Price]]) -> TRUE | M57: =ISNUMBER(Table3[[#This Row],[Order Date]]) -> TRUE | N57: =IFERROR(IF(Table3[[#This Row],[Quantity]]*Table3[[#This Row],[Unit Price]]<0, "N/A", Table3[[#This Row],[Quantity]]*Table3[[#This Row],[Unit Price]]), "N/A") -> 700000 | O57: =IFERROR(Table3[[#This Row],[Unit Price]]*Table3[[#This Row],[Return Qty]], "N/A") -> 0 | P57: =IFERROR(IF((Table3[[#This Row],[Revenue before return]]-Table3[[#This Row],[Amount of order returned]])<0, "N/A", Table3[[#This Row],[Revenue before return]]-Table3[[#This Row],[Amount of order returned]]), "N/A") -> 700000 | Q57: =IF(AND(Table3[[#This Row],[are branches correct]]=TRUE, Table3[[#This Row],[is quantity sold > quantity returned?]]=TRUE, Table3[[#This Row],[Unit price is valid]]=TRUE,Table3[[#This Row],[is the date valid]]=TRUE,Table3[[#This Row],[valid QTY]]=TRUE), "No action required", "Inspect") -> No action required
A58: T00057 | B58: Lagos | C58: Rice | D58: 24 | E58: 50000 | F58: C0254 | G58: 46112 | H58: 0 | I58: =IF(OR('CAL-DATA VALIDATION'!$A$2=Table3[[#This Row],[Branch]], 'CAL-DATA VALIDATION'!$A$3=Table3[[#This Row],[Branch]],'CAL-DATA VALIDATION'!$A$4=Table3[[#This Row],[Branch]],'CAL-DATA VALIDATION'!$A$5=Table3[[#This Row],[Branch]]), TRUE, FALSE) -> TRUE | J58: =((ISNUMBER(Table3[[#This Row],[Quantity]]) )* (Table3[[#This Row],[Quantity]]>0))=1 -> TRUE | K58: =((Table3[[#This Row],[Quantity]]>=Table3[[#This Row],[Return Qty]])*(ISNUMBER(Table3[[#This Row],[Quantity]])))=1 -> TRUE | L58: =ISNUMBER(Table3[[#This Row],[Unit Price]]) -> TRUE | M58: =ISNUMBER(Table3[[#This Row],[Order Date]]) -> TRUE | N58: =IFERROR(IF(Table3[[#This Row],[Quantity]]*Table3[[#This Row],[Unit Price]]<0, "N/A", Table3[[#This Row],[Quantity]]*Table3[[#This Row],[Unit Price]]), "N/A") -> 1200000 | O58: =IFERROR(Table3[[#This Row],[Unit Price]]*Table3[[#This Row],[Return Qty]], "N/A") -> 0 | P58: =IFERROR(IF((Table3[[#This Row],[Revenue before return]]-Table3[[#This Row],[Amount of order returned]])<0, "N/A", Table3[[#This Row],[Revenue before return]]-Table3[[#This Row],[Amount of order returned]]), "N/A") -> 1200000 | Q58: =IF(AND(Table3[[#This Row],[are branches correct]]=TRUE, Table3[[#This Row],[is quantity sold > quantity returned?]]=TRUE, Table3[[#This Row],[Unit price is valid]]=TRUE,Table3[[#This Row],[is the date valid]]=TRUE,Table3[[#This Row],[valid QTY]]=TRUE), "No action required", "Inspect") -> No action required
A59: T00058 | B59: Ibadan | C59: Chicken | D59: 20 | E59: 17500 | F59: C0222 | G59: 46095 | H59: 0 | I59: =IF(OR('CAL-DATA VALIDATION'!$A$2=Table3[[#This Row],[Branch]], 'CAL-DATA VALIDATION'!$A$3=Table3[[#This Row],[Branch]],'CAL-DATA VALIDATION'!$A$4=Table3[[#This Row],[Branch]],'CAL-DATA VALIDATION'!$A$5=Table3[[#This Row],[Branch]]), TRUE, FALSE) -> TRUE | J59: =((ISNUMBER(Table3[[#This Row],[Quantity]]) )* (Table3[[#This Row],[Quantity]]>0))=1 -> TRUE | K59: =((Table3[[#This Row],[Quantity]]>=Table3[[#This Row],[Return Qty]])*(ISNUMBER(Table3[[#This Row],[Quantity]])))=1 -> TRUE | L59: =ISNUMBER(Table3[[#This Row],[Unit Price]]) -> TRUE | M59: =ISNUMBER(Table3[[#This Row],[Order Date]]) -> TRUE | N59: =IFERROR(IF(Table3[[#This Row],[Quantity]]*Table3[[#This Row],[Unit Price]]<0, "N/A", Table3[[#This Row],[Quantity]]*Table3[[#This Row],[Unit Price]]), "N/A") -> 350000 | O59: =IFERROR(Table3[[#This Row],[Unit Price]]*Table3[[#This Row],[Return Qty]], "N/A") -> 0 | P59: =IFERROR(IF((Table3[[#This Row],[Revenue before return]]-Table3[[#This Row],[Amount of order returned]])<0, "N/A", Table3[[#This Row],[Revenue before return]]-Table3[[#This Row],[Amount of order returned]]), "N/A") -> 350000 | Q59: =IF(AND(Table3[[#This Row],[are branches correct]]=TRUE, Table3[[#This Row],[is quantity sold > quantity returned?]]=TRUE, Table3[[#This Row],[Unit price is valid]]=TRUE,Table3[[#This Row],[is the date valid]]=TRUE,Table3[[#This Row],[valid QTY]]=TRUE), "No action required", "Inspect") -> No action required
A60: T00059 | B60: Abuja | C60: Cooking Oil | D60: 15 | E60: 28000 | F60: C0189 | G60: 46058 | H60: 0 | I60: =IF(OR('CAL-DATA VALIDATION'!$A$2=Table3[[#This Row],[Branch]], 'CAL-DATA VALIDATION'!$A$3=Table3[[#This Row],[Branch]],'CAL-DATA VALIDATION'!$A$4=Table3[[#This Row],[Branch]],'CAL-DATA VALIDATION'!$A$5=Table3[[#This Row],[Branch]]), TRUE, FALSE) -> TRUE | J60: =((ISNUMBER(Table3[[#This Row],[Quantity]]) )* (Table3[[#This Row],[Quantity]]>0))=1 -> TRUE | K60: =((Table3[[#This Row],[Quantity]]>=Table3[[#This Row],[Return Qty]])*(ISNUMBER(Table3[[#This Row],[Quantity]])))=1 -> TRUE | L60: =ISNUMBER(Table3[[#This Row],[Unit Price]]) -> TRUE | M60: =ISNUMBER(Table3[[#This Row],[Order Date]]) -> TRUE | N60: =IFERROR(IF(Table3[[#This Row],[Quantity]]*Table3[[#This Row],[Unit Price]]<0, "N/A", Table3[[#This Row],[Quantity]]*Table3[[#This Row],[Unit Price]]), "N/A") -> 420000 | O60: =IFERROR(Table3[[#This Row],[Unit Price]]*Table3[[#This Row],[Return Qty]], "N/A") -> 0 | P60: =IFERROR(IF((Table3[[#This Row],[Revenue before return]]-Table3[[#This Row],[Amount of order returned]])<0, "N/A", Table3[[#This Row],[Revenue before return]]-Table3[[#This Row],[Amount of order returned]]), "N/A") -> 420000 | Q60: =IF(AND(Table3[[#This Row],[are branches correct]]=TRUE, Table3[[#This Row],[is quantity sold > quantity returned?]]=TRUE, Table3[[#This Row],[Unit price is valid]]=TRUE,Table3[[#This Row],[is the date valid]]=TRUE,Table3[[#This Row],[valid QTY]]=TRUE), "No action required", "Inspect") -> No action required
... A71: T00070 | B71: Ibadan | C71: Bread | D71: 1 | E71: 20000 | F71: C0040 | G71: 46051 | H71: 0 | I71: =IF(OR('CAL-DATA VALIDATION'!$A$2=Table3[[#This Row],[Branch]], 'CAL-DATA VALIDATION'!$A$3=Table3[[#This Row],[Branch]],'CAL-DATA VALIDATION'!$A$4=Table3[[#This Row],[Branch]],'CAL-DATA VALIDATION'!$A$5=Table3[[#This Row],[Branch]]), TRUE, FALSE) -> TRUE | J71: =((ISNUMBER(Table3[[#This Row],[Quantity]]) )* (Table3[[#This Row],[Quantity]]>0))=1 -> TRUE | K71: =((Table3[[#This Row],[Quantity]]>=Table3[[#This Row],[Return Qty]])*(ISNUMBER(Table3[[#This Row],[Quantity]])))=1 -> TRUE | L71: =ISNUMBER(Table3[[#This Row],[Unit Price]]) -> TRUE | M71: =ISNUMBER(Table3[[#This Row],[Order Date]]) -> TRUE | N71: =IFERROR(IF(Table3[[#This Row],[Quantity]]*Table3[[#This Row],[Unit Price]]<0, "N/A", Table3[[#This Row],[Quantity]]*Table3[[#This Row],[Unit Price]]), "N/A") -> 20000 | O71: =IFERROR(Table3[[#This Row],[Unit Price]]*Table3[[#This Row],[Return Qty]], "N/A") -> 0 | P71: =IFERROR(IF((Table3[[#This Row],[Revenue before return]]-Table3[[#This Row],[Amount of order returned]])<0, "N/A", Table3[[#This Row],[Revenue before return]]-Table3[[#This Row],[Amount of order returned]]), "N/A") -> 20000 | Q71: =IF(AND(Table3[[#This Row],[are branches correct]]=TRUE, Table3[[#This Row],[is quantity sold > quantity returned?]]=TRUE, Table3[[#This Row],[Unit price is valid]]=TRUE,Table3[[#This Row],[is the date valid]]=TRUE,Table3[[#This Row],[valid QTY]]=TRUE), "No action required", "Inspect") -> No action required
A72: T00071 | B72: Lagos | C72: Cooking Oil | D72: 24 | E72: 28000 | F72: C0045 | G72: N/A | H72: 0 | I72: =IF(OR('CAL-DATA VALIDATION'!$A$2=Table3[[#This Row],[Branch]], 'CAL-DATA VALIDATION'!$A$3=Table3[[#This Row],[Branch]],'CAL-DATA VALIDATION'!$A$4=Table3[[#This Row],[Branch]],'CAL-DATA VALIDATION'!$A$5=Table3[[#This Row],[Branch]]), TRUE, FALSE) -> TRUE | J72: =((ISNUMBER(Table3[[#This Row],[Quantity]]) )* (Table3[[#This Row],[Quantity]]>0))=1 -> TRUE | K72: =((Table3[[#This Row],[Quantity]]>=Table3[[#This Row],[Return Qty]])*(ISNUMBER(Table3[[#This Row],[Quantity]])))=1 -> TRUE | L72: =ISNUMBER(Table3[[#This Row],[Unit Price]]) -> TRUE | M72: =ISNUMBER(Table3[[#This Row],[Order Date]]) -> FALSE | N72: =IFERROR(IF(Table3[[#This Row],[Quantity]]*Table3[[#This Row],[Unit Price]]<0, "N/A", Table3[[#This Row],[Quantity]]*Table3[[#This Row],[Unit Price]]), "N/A") -> 672000 | O72: =IFERROR(Table3[[#This Row],[Unit Price]]*Table3[[#This Row],[Return Qty]], "N/A") -> 0 | P72: =IFERROR(IF((Table3[[#This Row],[Revenue before return]]-Table3[[#This Row],[Amount of order returned]])<0, "N/A", Table3[[#This Row],[Revenue before return]]-Table3[[#This Row],[Amount of order returned]]), "N/A") -> 672000 | Q72: =IF(AND(Table3[[#This Row],[are branches correct]]=TRUE, Table3[[#This Row],[is quantity sold > quantity returned?]]=TRUE, Table3[[#This Row],[Unit price is valid]]=TRUE,Table3[[#This Row],[is the date valid]]=TRUE,Table3[[#This Row],[valid QTY]]=TRUE), "No action required", "Inspect") -> Inspect
A73: T00072 | B73: Ibadan | C73: Chicken | D73: 23 | E73: 35000 | F73: C0224 | G73: 46153 | H73: 0 | I73: =IF(OR('CAL-DATA VALIDATION'!$A$2=Table3[[#This Row],[Branch]], 'CAL-DATA VALIDATION'!$A$3=Table3[[#This Row],[Branch]],'CAL-DATA VALIDATION'!$A$4=Table3[[#This Row],[Branch]],'CAL-DATA VALIDATION'!$A$5=Table3[[#This Row],[Branch]]), TRUE, FALSE) -> TRUE | J73: =((ISNUMBER(Table3[[#This Row],[Quantity]]) )* (Table3[[#This Row],[Quantity]]>0))=1 -> TRUE | K73: =((Table3[[#This Row],[Quantity]]>=Table3[[#This Row],[Return Qty]])*(ISNUMBER(Table3[[#This Row],[Quantity]])))=1 -> TRUE | L73: =ISNUMBER(Table3[[#This Row],[Unit Price]]) -> TRUE | M73: =ISNUMBER(Table3[[#This Row],[Order Date]]) -> TRUE | N73: =IFERROR(IF(Table3[[#This Row],[Quantity]]*Table3[[#This Row],[Unit Price]]<0, "N/A", Table3[[#This Row],[Quantity]]*Table3[[#This Row],[Unit Price]]), "N/A") -> 805000 | O73: =IFERROR(Table3[[#This Row],[Unit Price]]*Table3[[#This Row],[Return Qty]], "N/A") -> 0 | P73: =IFERROR(IF((Table3[[#This Row],[Revenue before return]]-Table3[[#This Row],[Amount of order returned]])<0, "N/A", Table3[[#This Row],[Revenue before return]]-Table3[[#This Row],[Amount of order returned]]), "N/A") -> 805000 | Q73: =IF(AND(Table3[[#This Row],[are branches correct]]=TRUE, Table3[[#This Row],[is quantity sold > quantity returned?]]=TRUE, Table3[[#This Row],[Unit price is valid]]=TRUE,Table3[[#This Row],[is the date valid]]=TRUE,Table3[[#This Row],[valid QTY]]=TRUE), "No action required", "Inspect") -> No action required
A74: T00073 | B74: Abuja | C74: Tomato | D74: 24 | E74: 8000 | F74: C0141 | G74: 46163 | H74: 0 | I74: =IF(OR('CAL-DATA VALIDATION'!$A$2=Table3[[#This Row],[Branch]], 'CAL-DATA VALIDATION'!$A$3=Table3[[#This Row],[Branch]],'CAL-DATA VALIDATION'!$A$4=Table3[[#This Row],[Branch]],'CAL-DATA VALIDATION'!$A$5=Table3[[#This Row],[Branch]]), TRUE, FALSE) -> TRUE | J74: =((ISNUMBER(Table3[[#This Row],[Quantity]]) )* (Table3[[#This Row],[Quantity]]>0))=1 -> TRUE | K74: =((Table3[[#This Row],[Quantity]]>=Table3[[#This Row],[Return Qty]])*(ISNUMBER(Table3[[#This Row],[Quantity]])))=1 -> TRUE | L74: =ISNUMBER(Table3[[#This Row],[Unit Price]]) -> TRUE | M74: =ISNUMBER(Table3[[#This Row],[Order Date]]) -> TRUE | N74: =IFERROR(IF(Table3[[#This Row],[Quantity]]*Table3[[#This Row],[Unit Price]]<0, "N/A", Table3[[#This Row],[Quantity]]*Table3[[#This Row],[Unit Price]]), "N/A") -> 192000 | O74: =IFERROR(Table3[[#This Row],[Unit Price]]*Table3[[#This Row],[Return Qty]], "N/A") -> 0 | P74: =IFERROR(IF((Table3[[#This Row],[Revenue before return]]-Table3[[#This Row],[Amount of order returned]])<0, "N/A", Table3[[#This Row],[Revenue before return]]-Table3[[#This Row],[Amount of order returned]]), "N/A") -> 192000 | Q74: =IF(AND(Table3[[#This Row],[are branches correct]]=TRUE, Table3[[#This Row],[is quantity sold > quantity returned?]]=TRUE, Table3[[#This Row],[Unit price is valid]]=TRUE,Table3[[#This Row],[is the date valid]]=TRUE,Table3[[#This Row],[valid QTY]]=TRUE), "No action required", "Inspect") -> No action required
A75: T00074 | B75: Port Harcourt | C75: Pasta | D75: 1 | E75: 15000 | F75: C0065 | G75: 46076 | H75: 0 | I75: =IF(OR('CAL-DATA VALIDATION'!$A$2=Table3[[#This Row],[Branch]], 'CAL-DATA VALIDATION'!$A$3=Table3[[#This Row],[Branch]],'CAL-DATA VALIDATION'!$A$4=Table3[[#This Row],[Branch]],'CAL-DATA VALIDATION'!$A$5=Table3[[#This Row],[Branch]]), TRUE, FALSE) -> TRUE | J75: =((ISNUMBER(Table3[[#This Row],[Quantity]]) )* (Table3[[#This Row],[Quantity]]>0))=1 -> TRUE | K75: =((Table3[[#This Row],[Quantity]]>=Table3[[#This Row],[Return Qty]])*(ISNUMBER(Table3[[#This Row],[Quantity]])))=1 -> TRUE | L75: =ISNUMBER(Table3[[#This Row],[Unit Price]]) -> TRUE | M75: =ISNUMBER(Table3[[#This Row],[Order Date]]) -> TRUE | N75: =IFERROR(IF(Table3[[#This Row],[Quantity]]*Table3[[#This Row],[Unit Price]]<0, "N/A", Table3[[#This Row],[Quantity]]*Table3[[#This Row],[Unit Price]]), "N/A") -> 15000 | O75: =IFERROR(Table3[[#This Row],[Unit Price]]*Table3[[#This Row],[Return Qty]], "N/A") -> 0 | P75: =IFERROR(IF((Table3[[#This Row],[Revenue before return]]-Table3[[#This Row],[Amount of order returned]])<0, "N/A", Table3[[#This Row],[Revenue before return]]-Table3[[#This Row],[Amount of order returned]]), "N/A") -> 15000 | Q75: =IF(AND(Table3[[#This Row],[are branches correct]]=TRUE, Table3[[#This Row],[is quantity sold > quantity returned?]]=TRUE, Table3[[#This Row],[Unit price is valid]]=TRUE,Table3[[#This Row],[is the date valid]]=TRUE,Table3[[#This Row],[valid QTY]]=TRUE), "No action required", "Inspect") -> No action required
